#include<stdexcept>
#include<iostream>
#include "main2.h"
int main() {
    // Uso de la versión que devuelve un valor de error
    int resultError = divideError(5, 0);
    if (resultError == -1) {
        std::cout << "Error: división por cero." << std::endl;
    }

    // Uso de la versión que lanza una excepción
    try {
        int resultException = divideException(5, 0);
    }
    catch (const std::invalid_argument& e) {
        std::cout << "Excepción: " << e.what() << std::endl;
    }

    return 0;
}